2024-12-28 19:49:37,753 INFO    StreamThr :104663 [internal.py:wandb_internal():90] W&B internal server running at pid: 104663, started at: 2024-12-28 19:49:37.752808
2024-12-28 19:49:37,755 DEBUG   HandlerThread:104663 [handler.py:handle_request():141] handle_request: status
2024-12-28 19:49:37,756 DEBUG   SenderThread:104663 [sender.py:send_request():246] send_request: status
2024-12-28 19:49:37,758 DEBUG   SenderThread:104663 [sender.py:send():232] send: header
2024-12-28 19:49:37,758 INFO    WriterThread:104663 [datastore.py:open_for_write():75] open: /home/awc2159/projects/MeTra_3D/outputs/2024-12-28/19-49-36/wandb/run-20241228_194937-3c3ua8sy/run-3c3ua8sy.wandb
2024-12-28 19:49:37,775 DEBUG   SenderThread:104663 [sender.py:send():232] send: run
2024-12-28 19:49:37,776 INFO    SenderThread:104663 [sender.py:_maybe_setup_resume():489] checking resume status for infinite_imaging/combine_image_and_text/3c3ua8sy
2024-12-28 19:49:38,193 ERROR   SenderThread:104663 [internal_api.py:execute():143] 403 response executing GraphQL.
2024-12-28 19:49:38,193 ERROR   SenderThread:104663 [internal_api.py:execute():144] {"errors":[{"message":"permission denied","path":["upsertBucket"],"extensions":{"code":"PERMISSION_ERROR"}}],"data":{"upsertBucket":null}}
2024-12-28 19:49:38,775 INFO    WriterThread:104663 [datastore.py:close():279] close: /home/awc2159/projects/MeTra_3D/outputs/2024-12-28/19-49-36/wandb/run-20241228_194937-3c3ua8sy/run-3c3ua8sy.wandb
2024-12-28 19:49:38,776 INFO    HandlerThread:104663 [handler.py:finish():806] shutting down handler
2024-12-28 19:49:38,776 ERROR   StreamThr :104663 [internal.py:wandb_internal():165] Thread SenderThread:
Traceback (most recent call last):
  File "/home/awc2159/.conda/envs/metra/lib/python3.8/site-packages/wandb/sdk/lib/retry.py", line 102, in __call__
    result = self._call_fn(*args, **kwargs)
  File "/home/awc2159/.conda/envs/metra/lib/python3.8/site-packages/wandb/sdk/internal/internal_api.py", line 140, in execute
    return self.client.execute(*args, **kwargs)
  File "/home/awc2159/.conda/envs/metra/lib/python3.8/site-packages/wandb/vendor/gql-0.2.0/wandb_gql/client.py", line 52, in execute
    result = self._get_result(document, *args, **kwargs)
  File "/home/awc2159/.conda/envs/metra/lib/python3.8/site-packages/wandb/vendor/gql-0.2.0/wandb_gql/client.py", line 60, in _get_result
    return self.transport.execute(document, *args, **kwargs)
  File "/home/awc2159/.conda/envs/metra/lib/python3.8/site-packages/wandb/vendor/gql-0.2.0/wandb_gql/transport/requests.py", line 39, in execute
    request.raise_for_status()
  File "/home/awc2159/.conda/envs/metra/lib/python3.8/site-packages/requests/models.py", line 1024, in raise_for_status
    raise HTTPError(http_error_msg, response=self)
requests.exceptions.HTTPError: 403 Client Error: Forbidden for url: https://api.wandb.ai/graphql

During handling of the above exception, another exception occurred:

Traceback (most recent call last):
  File "/home/awc2159/.conda/envs/metra/lib/python3.8/site-packages/wandb/apis/normalize.py", line 22, in wrapper
    return func(*args, **kwargs)
  File "/home/awc2159/.conda/envs/metra/lib/python3.8/site-packages/wandb/sdk/internal/internal_api.py", line 1318, in upsert_run
    response = self.gql(mutation, variable_values=variable_values, **kwargs)
  File "/home/awc2159/.conda/envs/metra/lib/python3.8/site-packages/wandb/sdk/lib/retry.py", line 118, in __call__
    if not check_retry_fn(e):
  File "/home/awc2159/.conda/envs/metra/lib/python3.8/site-packages/wandb/util.py", line 879, in no_retry_auth
    raise CommError("Permission denied, ask the project owner to grant you access")
wandb.errors.CommError: Permission denied, ask the project owner to grant you access

During handling of the above exception, another exception occurred:

Traceback (most recent call last):
  File "/home/awc2159/.conda/envs/metra/lib/python3.8/site-packages/wandb/sdk/internal/internal_util.py", line 51, in run
    self._run()
  File "/home/awc2159/.conda/envs/metra/lib/python3.8/site-packages/wandb/sdk/internal/internal_util.py", line 102, in _run
    self._process(record)
  File "/home/awc2159/.conda/envs/metra/lib/python3.8/site-packages/wandb/sdk/internal/internal.py", line 310, in _process
    self._sm.send(record)
  File "/home/awc2159/.conda/envs/metra/lib/python3.8/site-packages/wandb/sdk/internal/sender.py", line 234, in send
    send_handler(record)
  File "/home/awc2159/.conda/envs/metra/lib/python3.8/site-packages/wandb/sdk/internal/sender.py", line 692, in send_run
    self._init_run(run, config_value_dict)
  File "/home/awc2159/.conda/envs/metra/lib/python3.8/site-packages/wandb/sdk/internal/sender.py", line 716, in _init_run
    server_run, inserted = self._api.upsert_run(
  File "/home/awc2159/.conda/envs/metra/lib/python3.8/site-packages/wandb/apis/normalize.py", line 58, in wrapper
    raise CommError(message, err).with_traceback(sys.exc_info()[2])
  File "/home/awc2159/.conda/envs/metra/lib/python3.8/site-packages/wandb/apis/normalize.py", line 22, in wrapper
    return func(*args, **kwargs)
  File "/home/awc2159/.conda/envs/metra/lib/python3.8/site-packages/wandb/sdk/internal/internal_api.py", line 1318, in upsert_run
    response = self.gql(mutation, variable_values=variable_values, **kwargs)
  File "/home/awc2159/.conda/envs/metra/lib/python3.8/site-packages/wandb/sdk/lib/retry.py", line 118, in __call__
    if not check_retry_fn(e):
  File "/home/awc2159/.conda/envs/metra/lib/python3.8/site-packages/wandb/util.py", line 879, in no_retry_auth
    raise CommError("Permission denied, ask the project owner to grant you access")
wandb.errors.CommError: Permission denied, ask the project owner to grant you access
